<?xml version="1.0" ?>
<!-- =================================================================================== -->
<!-- |    This document was autogenerated by xacro from meshes/urdf/aloha.urdf.xacro | -->
<!-- |    EDITING THIS FILE BY HAND IS NOT RECOMMENDED                                 | -->
<!-- =================================================================================== -->
<robot name="bimanual_viperx_transfer_cube">
  <!-- map link -->
  <link name="map"/>

  <!-- jigu -->
  <link name="jigu">
    <visual>
      <origin rpy="0 0 0" xyz="0 0 0"/>
      <geometry>
        <mesh filename="meshes/aloha_v1_assembly_jigu.obj" scale="1 1 1"/>
      </geometry>
      <material name="grey">
        <color rgba="0.2 0.2 0.2 1.0"/>
      </material>
    </visual>
    <collision>
      <origin rpy="0 0 0" xyz="0 0 0"/>
      <geometry>
        <mesh filename="meshes/aloha_v1_assembly_jigu.obj" scale="1 1 1"/>
      </geometry>
    </collision>
    <inertial>
      <mass value="10.0"/>
      <origin xyz="0 0 0"/>
      <inertia ixx="1.0" ixy="0.0" ixz="0.0" iyy="1.0" iyz="0.0" izz="1.0"/>
    </inertial>
  </link>
  <joint name="map_to_jigu" type="fixed">
    <parent link="map"/>
    <child link="jigu"/>
    <origin rpy="0 0 0" xyz="0 0.19 -0.02"/>
  </joint>
  <!-- mount -->
  <link name="mount">
    <visual>
      <origin rpy="0 0 0" xyz="0 0 0"/>
      <geometry>
        <mesh filename="meshes/aloha_v1_assembly_mount.obj" scale="1 1 1"/>
      </geometry>
      <material name="grey">
        <color rgba="0.2 0.2 0.2 1.0"/>
      </material>
    </visual>
    <collision>
      <origin rpy="0 0 0" xyz="0 0 0"/>
      <geometry>
        <mesh filename="meshes/aloha_v1_assembly_mount.obj" scale="1 1 1"/>
      </geometry>
    </collision>
    <inertial>
      <mass value="10.0"/>
      <origin xyz="0 0 0"/>
      <inertia ixx="1.0" ixy="0.0" ixz="0.0" iyy="1.0" iyz="0.0" izz="1.0"/>
    </inertial>
  </link>
  <joint name="map_to_mount" type="fixed">
    <parent link="map"/>
    <child link="mount"/>
    <origin rpy="0 0 0" xyz="0 0.19 -0.02"/>
  </joint>
  <!-- pole -->
  <link name="pole">
    <visual>
      <origin rpy="0 0 0" xyz="0 0 0"/>
      <geometry>
        <mesh filename="meshes/aloha_v1_assembly_pole.obj" scale="1 1 1"/>
      </geometry>
      <material name="grey">
        <color rgba="0.2 0.2 0.2 1.0"/>
      </material>
    </visual>
    <collision>
      <origin rpy="0 0 0" xyz="0 0 0"/>
      <geometry>
        <mesh filename="meshes/aloha_v1_assembly_pole.obj" scale="1 1 1"/>
      </geometry>
    </collision>
    <inertial>
      <mass value="10.0"/>
      <origin xyz="0 0 0"/>
      <inertia ixx="1.0" ixy="0.0" ixz="0.0" iyy="1.0" iyz="0.0" izz="1.0"/>
    </inertial>
  </link>
  <joint name="map_to_pole" type="fixed">
    <parent link="map"/>
    <child link="pole"/>
    <origin rpy="0 0 0" xyz="0 0.19 -0.02"/>
  </joint>
  <!-- table -->
  <link name="table">
    <visual>
      <origin rpy="0 0 0" xyz="0 0 0"/>
      <geometry>
        <mesh filename="meshes/aloha_v1_assembly_table.obj" scale="1 1 1"/>
      </geometry>
      <material name="grey">
        <color rgba="0.2 0.2 0.2 1.0"/>
      </material>
    </visual>
    <collision>
      <origin rpy="0 0 0" xyz="0 0 0"/>
      <geometry>
        <mesh filename="meshes/aloha_v1_assembly_table.obj" scale="1 1 1"/>
      </geometry>
    </collision>
    <inertial>
      <mass value="10.0"/>
      <origin xyz="0 0 0"/>
      <inertia ixx="1.0" ixy="0.0" ixz="0.0" iyy="1.0" iyz="0.0" izz="1.0"/>
    </inertial>
  </link>
  <joint name="map_to_table" type="fixed">
    <parent link="map"/>
    <child link="table"/>
    <origin rpy="0 0 0" xyz="0 0.19 -0.02"/>
  </joint>
 
  <!-- *********************** LEFT ARM ***************************** -->
  <!-- vx300s_left_base -->
  <link name="vx300s_left_base">
    <visual>
      <origin rpy="0 0 1.5708" xyz="0 0 0"/>
      <geometry>
        <mesh filename="meshes/vx300s_1_base.stl" scale="0.001 0.001 0.001"/>
      </geometry>
    </visual>
    <collision>
      <origin rpy="0 0 1.5708" xyz="0 0 0"/>
      <geometry>
        <mesh filename="meshes/vx300s_1_base.stl" scale="0.001 0.001 0.001"/>
      </geometry>
    </collision>
    <inertial>
      <mass value="1.0"/>
      <origin xyz="0 0 0"/>
      <inertia ixx="0.01" ixy="0" ixz="0" iyy="0.01" iyz="0" izz="0.01"/>
    </inertial>
  </link>
  <joint name="map_to_vx300s_left_base" type="fixed">
    <parent link="map"/>
    <child link="vx300s_left_base"/>
    <origin rpy="0 0 0" xyz="-0.469 0.5 0"/>
  </joint>
  <!-- vx300s_left_shoulder_link -->
  <link name="vx300s_left_shoulder_link">
    <visual>
      <origin rpy="0 0 1.5708" xyz="0 0 -0.003"/>
      <geometry>
        <mesh filename="meshes/vx300s_2_shoulder.stl" scale="0.001 0.001 0.001"/>
      </geometry>
    </visual>
    <collision>
      <origin rpy="0 0 1.5708" xyz="0 0 -0.003"/>
      <geometry>
        <mesh filename="meshes/vx300s_2_shoulder.stl" scale="0.001 0.001 0.001"/>
      </geometry>
    </collision>
    <inertial>
      <mass value="0.8"/>
      <origin xyz="0 0 0.0116"/>
      <inertia ixx="0.00120156" ixy="0" ixz="0" iyy="0.00113744" iyz="0" izz="0.0009388"/>
    </inertial>
  </link>
  <joint name="vx300s_left_waist" type="revolute">
    <parent link="vx300s_left_base"/>
    <child link="vx300s_left_shoulder_link"/>
    <origin rpy="0 0 0" xyz="0 0 0.079"/>
    <axis xyz="0 0 1"/>
    <limit effort="100" lower="-3.14158" upper="3.14158" velocity="1.0"/>
  </joint>
  <!-- vx300s_left_upper_arm_link -->
  <link name="vx300s_left_upper_arm_link">
    <visual>
      <origin rpy="0 0 1.5708" xyz="0 0 0"/>
      <geometry>
        <mesh filename="meshes/vx300s_3_upper_arm.stl" scale="0.001 0.001 0.001"/>
      </geometry>
    </visual>
    <collision>
      <origin rpy="0 0 1.5708" xyz="0 0 0"/>
      <geometry>
        <mesh filename="meshes/vx300s_3_upper_arm.stl" scale="0.001 0.001 0.001"/>
      </geometry>
    </collision>
    <inertial>
      <mass value="0.79"/>
      <origin xyz="0.0207 0 0.226"/>
      <inertia ixx="0.00911338" ixy="0" ixz="0" iyy="0.008925" iyz="0" izz="0.000759317"/>
    </inertial>
  </link>
  <joint name="vx300s_left_shoulder" type="revolute">
    <parent link="vx300s_left_shoulder_link"/>
    <child link="vx300s_left_upper_arm_link"/>
    <origin rpy="0 -0.5 0" xyz="0 0 0.04805"/>
    <axis xyz="0 1 0"/>
    <limit effort="100" lower="-1.85005" upper="1.25664" velocity="1.0"/>
  </joint>
  <!-- vx300s_left_upper_forearm_link -->
  <link name="vx300s_left_upper_forearm_link">
    <visual>
      <origin rpy="0 0 0" xyz="0 0 0"/>
      <geometry>
        <mesh filename="meshes/vx300s_4_upper_forearm.stl" scale="0.001 0.001 0.001"/>
      </geometry>
    </visual>
    <collision>
      <origin rpy="0 0 0" xyz="0 0 0"/>
      <geometry>
        <mesh filename="meshes/vx300s_4_upper_forearm.stl" scale="0.001 0.001 0.001"/>
      </geometry>
    </collision>
    <inertial>
      <mass value="0.322"/>
      <origin xyz="0.1057 0 0"/>
      <inertia ixx="0.00144107" ixy="0" ixz="0" iyy="0.00134228" iyz="0" izz="0.000152047"/>
    </inertial>
  </link>
  <joint name="vx300s_left_elbow" type="revolute">
    <parent link="vx300s_left_upper_arm_link"/>
    <child link="vx300s_left_upper_forearm_link"/>
    <origin rpy="0 0 0" xyz="0.05955 0 0.3"/>
    <axis xyz="0 1 0"/>
    <limit effort="100" lower="-1.76278" upper="1.6057" velocity="1.0"/>
  </joint>
  <!-- vx300s_left_lower_forearm_link -->
  <link name="vx300s_left_lower_forearm_link">
    <visual>
      <origin rpy="3.1415 0 0" xyz="0 0 0"/>
      <geometry>
        <mesh filename="meshes/vx300s_5_lower_forearm.stl" scale="0.001 0.001 0.001"/>
      </geometry>
    </visual>
    <collision>
      <origin rpy="3.1415 0 0" xyz="0 0 0"/>
      <geometry>
        <mesh filename="meshes/vx300s_5_lower_forearm.stl" scale="0.001 0.001 0.001"/>
      </geometry>
    </collision>
    <inertial>
      <mass value="0.415"/>
      <origin xyz="0.0513 0.0068 0"/>
      <inertia ixx="0.0005911" ixy="0" ixz="0" iyy="0.000546493" iyz="0" izz="0.000155707"/>
    </inertial>
  </link>
  <joint name="vx300s_left_forearm_roll" type="revolute">
    <parent link="vx300s_left_upper_forearm_link"/>
    <child link="vx300s_left_lower_forearm_link"/>
    <origin rpy="0 0 0" xyz="0.2 0 0"/>
    <axis xyz="1 0 0"/>
    <limit effort="100" lower="-3.14158" upper="3.14158" velocity="1.0"/>
  </joint>
  <!-- vx300s_left_wrist_link -->
  <link name="vx300s_left_wrist_link">
    <visual>
      <origin rpy="0 0 1.5708" xyz="0 0 0"/>
      <geometry>
        <mesh filename="meshes/vx300s_6_wrist.stl" scale="0.001 0.001 0.001"/>
      </geometry>
    </visual>
    <collision>
      <origin rpy="0 0 1.5708" xyz="0 0 0"/>
      <geometry>
        <mesh filename="meshes/vx300s_6_wrist.stl" scale="0.001 0.001 0.001"/>
      </geometry>
    </collision>
    <inertial>
      <mass value="0.115"/>
      <origin xyz="0.0467 0 0.0106"/>
      <inertia ixx="5.457e-05" ixy="0" ixz="0" iyy="4.631e-05" iyz="0" izz="4.327e-05"/>
    </inertial>
  </link>
  <joint name="vx300s_left_wrist_angle" type="revolute">
    <parent link="vx300s_left_lower_forearm_link"/>
    <child link="vx300s_left_wrist_link"/>
    <origin rpy="0 0 0" xyz="0.1 0 0"/>
    <axis xyz="0 1 0"/>
    <limit effort="100" lower="-1.8675" upper="2.23402" velocity="1.0"/>
  </joint>
  <!-- vx300s_left_gripper_link -->
  <link name="vx300s_left_gripper_link">
    <visual>
      <origin rpy="0 0 1.5708" xyz="-0.02 0 0"/>
      <geometry>
        <mesh filename="meshes/vx300s_7_gripper.stl" scale="0.001 0.001 0.001"/>
      </geometry>
    </visual>
    <visual>
      <origin rpy="0 0 1.5708" xyz="-0.020175 0 0"/>
      <geometry>
        <mesh filename="meshes/vx300s_9_gripper_bar.stl" scale="0.001 0.001 0.001"/>
      </geometry>
    </visual>
    <collision>
      <origin rpy="0 0 1.5708" xyz="-0.02 0 0"/>
      <geometry>
        <mesh filename="meshes/vx300s_7_gripper.stl" scale="0.001 0.001 0.001"/>
      </geometry>
    </collision>
    <collision>
      <origin rpy="0 0 1.5708" xyz="-0.020175 0 0"/>
      <geometry>
        <mesh filename="meshes/vx300s_9_gripper_bar.stl" scale="0.001 0.001 0.001"/>
      </geometry>
    </collision>
    <inertial>
      <mass value="0.2517"/>
      <origin xyz="0.0396 0 0.004"/>
      <inertia ixx="0.000689546" ixy="0" ixz="0" iyy="0.000650316" iyz="0" izz="0.000468142"/>
    </inertial>
  </link>
  <joint name="vx300s_left_wrist_rotate" type="revolute">
    <parent link="vx300s_left_wrist_link"/>
    <child link="vx300s_left_gripper_link"/>
    <origin rpy="0 0 0" xyz="0.069744 0 0"/>
    <axis xyz="1 0 0"/>
    <limit effort="100" lower="-3.14158" upper="3.14158" velocity="1.0"/>
  </joint>
  <!-- vx300s_left_gripper_prop_link -->
  <link name="vx300s_left_gripper_prop_link">
    <visual>
      <origin rpy="0 0 1.5708" xyz="-0.0685 0 0"/>
      <geometry>
        <mesh filename="meshes/vx300s_8_gripper_prop.stl" scale="0.001 0.001 0.001"/>
      </geometry>
    </visual>
    <collision>
      <origin rpy="0 0 1.5708" xyz="-0.0685 0 0"/>
      <geometry>
        <mesh filename="meshes/vx300s_8_gripper_prop.stl" scale="0.001 0.001 0.001"/>
      </geometry>
    </collision>
    <inertial>
      <mass value="0.008009"/>
      <origin xyz="0 0 0"/>
      <inertia ixx="4.2979e-06" ixy="0" ixz="0" iyy="2.8868e-06" iyz="0" izz="1.5314e-06"/>
    </inertial>
  </link>
  <joint name="vx300s_left_gripper" type="revolute">
    <parent link="vx300s_left_gripper_link"/>
    <child link="vx300s_left_gripper_prop_link"/>
    <origin rpy="0 0 0" xyz="0.0485 0 0"/>
    <axis xyz="1 0 0"/>
    <limit effort="30" lower="0" upper="0" velocity="1.0"/>
  </joint>
  <!-- Left fingers -->
  <link name="vx300s_left_left_finger_link">
    <visual>
      <origin rpy="0 0 0" xyz="0 0 0"/>
      <geometry>
        <mesh filename="meshes/vx300s_10_custom_finger_left.stl" scale="0.001 0.001 0.001"/>
      </geometry>
    </visual>
    <collision>
      <origin rpy="0 0 0" xyz="0 0 0"/>
      <geometry>
        <mesh filename="meshes/vx300s_10_custom_finger_left.stl" scale="0.001 0.001 0.001"/>
      </geometry>
    </collision>
    <inertial>
      <mass value="0.0348"/>
      <origin xyz="0.0173 -0.006 0"/>
      <inertia ixx="2.48e-05" ixy="0" ixz="0" iyy="1.417e-05" iyz="0" izz="1.208e-05"/>
    </inertial>
  </link>
  <joint name="vx300s_left_left_finger" type="prismatic">
    <parent link="vx300s_left_gripper_link"/>
    <child link="vx300s_left_left_finger_link"/>
    <!-- <origin xyz="0 0 0" rpy="0 0 0"/> -->
    <origin rpy="0 1.57 0" xyz="0.0737 -0.031 0"/>
    <axis xyz="0 1 0"/>
    <limit effort="100" lower="0.0" upper="0.0605" velocity="1.0"/>
  </joint>
  <link name="vx300s_left_right_finger_link">
    <visual>
      <origin rpy="0 0 0" xyz="0 0 0"/>
      <geometry>
        <mesh filename="meshes/vx300s_10_custom_finger_right.stl" scale="0.001 0.001 0.001"/>
      </geometry>
    </visual>
    <collision>
      <origin rpy="3.14 1.57 0" xyz="0.0737 0 0.052"/>
      <geometry>
        <mesh filename="meshes/vx300s_10_custom_finger_right.stl" scale="0.001 0.001 0.001"/>
      </geometry>
    </collision>
    <inertial>
      <mass value="0.0348"/>
      <origin xyz="0.0173 0.006 0"/>
      <inertia ixx="2.48e-05" ixy="0" ixz="0" iyy="1.417e-05" iyz="0" izz="1.208e-05"/>
    </inertial>
  </link>
  <joint name="vx300s_left_right_finger" type="prismatic">
    <parent link="vx300s_left_gripper_link"/>
    <child link="vx300s_left_right_finger_link"/>
    <!-- <origin xyz="0 0 0" rpy="0 0 0"/> -->
    <origin rpy="0 1.57 0" xyz="0.0737 0.031 0.0"/>
    <axis xyz="0 1 0"/>
    <limit effort="100" lower="-0.0605" upper="-0.0" velocity="1.0"/>
    <mimic joint="vx300s_left_left_finger" multiplier="-1.0" offset="0.0"/>
  </joint>
  <!-- *********************** RIGHT ARM ***************************** -->
  <!-- vx300s_right_base -->
  <link name="vx300s_right_base">
    <visual>
      <origin rpy="0 0 1.5708" xyz="0 0 0"/>
      <geometry>
        <mesh filename="meshes/vx300s_1_base.stl" scale="0.001 0.001 0.001"/>
      </geometry>
    </visual>
    <collision>
      <origin rpy="0 0 1.5708" xyz="0 0 0"/>
      <geometry>
        <mesh filename="meshes/vx300s_1_base.stl" scale="0.001 0.001 0.001"/>
      </geometry>
    </collision>
    <inertial>
      <mass value="1.0"/>
      <origin xyz="0 0 0"/>
      <inertia ixx="0.01" ixy="0" ixz="0" iyy="0.01" iyz="0" izz="0.01"/>
    </inertial>
  </link>
  <joint name="map_to_vx300s_right_base" type="fixed">
    <parent link="map"/>
    <child link="vx300s_right_base"/>
    <origin rpy="0 0 3.1416" xyz="0.469 0.5 0"/>
  </joint>
  <!-- vx300s_right_shoulder_link -->
  <link name="vx300s_right_shoulder_link">
    <visual>
      <origin rpy="0 0 1.5708" xyz="0 0 -0.003"/>
      <geometry>
        <mesh filename="meshes/vx300s_2_shoulder.stl" scale="0.001 0.001 0.001"/>
      </geometry>
    </visual>
    <collision>
      <origin rpy="0 0 1.5708" xyz="0 0 -0.003"/>
      <geometry>
        <mesh filename="meshes/vx300s_2_shoulder.stl" scale="0.001 0.001 0.001"/>
      </geometry>
    </collision>
    <inertial>
      <mass value="0.8"/>
      <origin xyz="0 0 0.0116"/>
      <inertia ixx="0.00120156" ixy="0" ixz="0" iyy="0.00113744" iyz="0" izz="0.0009388"/>
    </inertial>
  </link>
  <joint name="vx300s_right_waist" type="revolute">
    <parent link="vx300s_right_base"/>
    <child link="vx300s_right_shoulder_link"/>
    <origin rpy="0 0 0" xyz="0 0 0.079"/>
    <axis xyz="0 0 1"/>
    <limit effort="100" lower="-3.14158" upper="3.14158" velocity="1.0"/>
  </joint>
  <!-- vx300s_right_upper_arm_link -->
  <link name="vx300s_right_upper_arm_link">
    <visual>
      <origin rpy="0 0 1.5708" xyz="0 0 0"/>
      <geometry>
        <mesh filename="meshes/vx300s_3_upper_arm.stl" scale="0.001 0.001 0.001"/>
      </geometry>
    </visual>
    <collision>
      <origin rpy="0 0 1.5708" xyz="0 0 0"/>
      <geometry>
        <mesh filename="meshes/vx300s_3_upper_arm.stl" scale="0.001 0.001 0.001"/>
      </geometry>
    </collision>
    <inertial>
      <mass value="0.79"/>
      <origin xyz="0.0207 0 0.226"/>
      <inertia ixx="0.00911338" ixy="0" ixz="0" iyy="0.008925" iyz="0" izz="0.000759317"/>
    </inertial>
  </link>
  <joint name="vx300s_right_shoulder" type="revolute">
    <parent link="vx300s_right_shoulder_link"/>
    <child link="vx300s_right_upper_arm_link"/>
    <origin rpy="0 -0.5 0" xyz="0 0 0.04805"/>
    <axis xyz="0 1 0"/>
    <limit effort="100" lower="-1.85005" upper="1.25664" velocity="1.0"/>
  </joint>
  <!-- vx300s_right_upper_forearm_link -->
  <link name="vx300s_right_upper_forearm_link">
    <visual>
      <origin rpy="0 0 0" xyz="0 0 0"/>
      <geometry>
        <mesh filename="meshes/vx300s_4_upper_forearm.stl" scale="0.001 0.001 0.001"/>
      </geometry>
    </visual>
    <collision>
      <origin rpy="0 0 0" xyz="0 0 0"/>
      <geometry>
        <mesh filename="meshes/vx300s_4_upper_forearm.stl" scale="0.001 0.001 0.001"/>
      </geometry>
    </collision>
    <inertial>
      <mass value="0.322"/>
      <origin xyz="0.1057 0 0"/>
      <inertia ixx="0.00144107" ixy="0" ixz="0" iyy="0.00134228" iyz="0" izz="0.000152047"/>
    </inertial>
  </link>
  <joint name="vx300s_right_elbow" type="revolute">
    <parent link="vx300s_right_upper_arm_link"/>
    <child link="vx300s_right_upper_forearm_link"/>
    <origin rpy="0 0 0" xyz="0.05955 0 0.3"/>
    <axis xyz="0 1 0"/>
    <limit effort="100" lower="-1.76278" upper="1.6057" velocity="1.0"/>
  </joint>
  <!-- vx300s_right_lower_forearm_link -->
  <link name="vx300s_right_lower_forearm_link">
    <visual>
      <origin rpy="3.1415 0 0" xyz="0 0 0"/>
      <geometry>
        <mesh filename="meshes/vx300s_5_lower_forearm.stl" scale="0.001 0.001 0.001"/>
      </geometry>
    </visual>
    <collision>
      <origin rpy="3.1415 0 0" xyz="0 0 0"/>
      <geometry>
        <mesh filename="meshes/vx300s_5_lower_forearm.stl" scale="0.001 0.001 0.001"/>
      </geometry>
    </collision>
    <inertial>
      <mass value="0.415"/>
      <origin xyz="0.0513 0.0068 0"/>
      <inertia ixx="0.0005911" ixy="0" ixz="0" iyy="0.000546493" iyz="0" izz="0.000155707"/>
    </inertial>
  </link>
  <joint name="vx300s_right_forearm_roll" type="revolute">
    <parent link="vx300s_right_upper_forearm_link"/>
    <child link="vx300s_right_lower_forearm_link"/>
    <origin rpy="0 0 0" xyz="0.2 0 0"/>
    <axis xyz="1 0 0"/>
    <limit effort="100" lower="-3.14158" upper="3.14158" velocity="1.0"/>
  </joint>
  <!-- vx300s_right_wrist_link -->
  <link name="vx300s_right_wrist_link">
    <visual>
      <origin rpy="0 0 1.5708" xyz="0 0 0"/>
      <geometry>
        <mesh filename="meshes/vx300s_6_wrist.stl" scale="0.001 0.001 0.001"/>
      </geometry>
    </visual>
    <collision>
      <origin rpy="0 0 1.5708" xyz="0 0 0"/>
      <geometry>
        <mesh filename="meshes/vx300s_6_wrist.stl" scale="0.001 0.001 0.001"/>
      </geometry>
    </collision>
    <inertial>
      <mass value="0.115"/>
      <origin xyz="0.0467 0 0.0106"/>
      <inertia ixx="5.457e-05" ixy="0" ixz="0" iyy="4.631e-05" iyz="0" izz="4.327e-05"/>
    </inertial>
  </link>
  <joint name="vx300s_right_wrist_angle" type="revolute">
    <parent link="vx300s_right_lower_forearm_link"/>
    <child link="vx300s_right_wrist_link"/>
    <origin rpy="0 0 0" xyz="0.1 0 0"/>
    <axis xyz="0 1 0"/>
    <limit effort="100" lower="-1.8675" upper="2.23402" velocity="1.0"/>
  </joint>
  <!-- vx300s_right_gripper_link -->
  <link name="vx300s_right_gripper_link">
    <visual>
      <origin rpy="0 0 1.5708" xyz="-0.02 0 0"/>
      <geometry>
        <mesh filename="meshes/vx300s_7_gripper.stl" scale="0.001 0.001 0.001"/>
      </geometry>
    </visual>
    <visual>
      <origin rpy="0 0 1.5708" xyz="-0.020175 0 0"/>
      <geometry>
        <mesh filename="meshes/vx300s_9_gripper_bar.stl" scale="0.001 0.001 0.001"/>
      </geometry>
    </visual>
    <collision>
      <origin rpy="0 0 1.5708" xyz="-0.02 0 0"/>
      <geometry>
        <mesh filename="meshes/vx300s_7_gripper.stl" scale="0.001 0.001 0.001"/>
      </geometry>
    </collision>
    <collision>
      <origin rpy="0 0 1.5708" xyz="-0.020175 0 0"/>
      <geometry>
        <mesh filename="meshes/vx300s_9_gripper_bar.stl" scale="0.001 0.001 0.001"/>
      </geometry>
    </collision>
    <inertial>
      <mass value="0.2517"/>
      <origin xyz="0.0396 0 0.004"/>
      <inertia ixx="0.000689546" ixy="0" ixz="0" iyy="0.000650316" iyz="0" izz="0.000468142"/>
    </inertial>
  </link>
  <joint name="vx300s_right_wrist_rotate" type="revolute">
    <parent link="vx300s_right_wrist_link"/>
    <child link="vx300s_right_gripper_link"/>
    <origin rpy="0 0 0" xyz="0.069744 0 0"/>
    <axis xyz="1 0 0"/>
    <limit effort="100" lower="-3.14158" upper="3.14158" velocity="1.0"/>
  </joint>
  <link name="vx300s_right_gripper_prop_link">
    <visual>
      <origin rpy="0 0 1.5708" xyz="-0.0685 0 0"/>
      <geometry>
        <mesh filename="meshes/vx300s_8_gripper_prop.stl" scale="0.001 0.001 0.001"/>
      </geometry>
    </visual>
    <collision>
      <origin rpy="0 0 1.5708" xyz="-0.0685 0 0"/>
      <geometry>
        <mesh filename="meshes/vx300s_8_gripper_prop.stl"/>
      </geometry>
    </collision>
    <inertial>
      <mass value="0.008009"/>
      <origin xyz="0 0 0"/>
      <inertia ixx="4.2979e-06" ixy="0" ixz="0" iyy="2.8868e-06" iyz="0" izz="1.5314e-06"/>
    </inertial>
  </link>
  <joint name="vx300s_right_gripper" type="revolute">
    <parent link="vx300s_right_gripper_link"/>
    <child link="vx300s_right_gripper_prop_link"/>
    <origin rpy="0 0 0" xyz="0.0485 0 0"/>
    <axis xyz="1 0 0"/>
    <limit effort="30" lower="0" upper="0" velocity="1.0"/>
  </joint>
  <link name="vx300s_right_left_finger_link">
    <visual>
      <origin rpy="0 0 0" xyz="0 0 0"/>
      <geometry>
        <mesh filename="meshes/vx300s_10_custom_finger_left.stl" scale="0.001 0.001 0.001"/>
      </geometry>
    </visual>
    <collision>
      <origin rpy="0 0 0" xyz="0 0 0"/>
      <geometry>
        <mesh filename="meshes/vx300s_10_custom_finger_left.stl" scale="0.001 0.001 0.001"/>
      </geometry>
    </collision>
    <inertial>
      <mass value="0.0348"/>
      <origin xyz="0.0173 -0.006 0"/>
      <inertia ixx="2.48e-05" ixy="0" ixz="0" iyy="1.417e-05" iyz="0" izz="1.208e-05"/>
    </inertial>
  </link>
  <joint name="vx300s_right_left_finger" type="prismatic">
    <parent link="vx300s_right_gripper_link"/>
    <child link="vx300s_right_left_finger_link"/>
    <origin rpy="0 1.57 0" xyz="0.0737 -0.031 0"/>
    <axis xyz="0 1 0"/>
    <limit effort="100" lower="0.0" upper="0.0605" velocity="1.0"/>
  </joint>
  <link name="vx300s_right_right_finger_link">
    <visual>
      <origin rpy="0 0 0" xyz="0 0 0"/>
      <geometry>
        <mesh filename="meshes/vx300s_10_custom_finger_right.stl" scale="0.001 0.001 0.001"/>
      </geometry>
    </visual>
    <collision>
      <origin rpy="0 0 0" xyz="0 0 0"/>
      <geometry>
        <mesh filename="meshes/vx300s_10_custom_finger_right.stl" scale="0.001 0.001 0.001"/>
      </geometry>
    </collision>
    <inertial>
      <mass value="0.0348"/>
      <origin xyz="0.0173 0.006 0"/>
      <inertia ixx="2.48e-05" ixy="0" ixz="0" iyy="1.417e-05" iyz="0" izz="1.208e-05"/>
    </inertial>
  </link>
  <joint name="vx300s_right_right_finger" type="prismatic">
    <parent link="vx300s_right_gripper_link"/>
    <child link="vx300s_right_right_finger_link"/>
    <origin rpy="0 1.57 0" xyz="0.0737 0.031 0.0"/>
    <axis xyz="0 1 0"/>
    <limit effort="100" lower="-0.0605" upper="-0.0" velocity="1.0"/>
    <mimic joint="vx300s_right_left_finger" multiplier="-1.0" offset="0.0"/>
  </joint>
  <link name="charuco_dmy_link">
    <visual>
      <origin rpy="0 0 0" xyz="0 0 0"/>
      <geometry>
        <mesh filename="meshes/charuco.obj" scale="1 1 1"/>
      </geometry>
    </visual>
    <collision>
      <origin rpy="0 0 0" xyz="0 0 0"/>
      <geometry>
        <mesh filename="meshes/charuco.obj" scale="1 1 1"/>
      </geometry>
    </collision>
    <inertial>
      <mass value="0.0348"/>
      <origin xyz="0.0173 0.006 0"/>
      <inertia ixx="2.48e-05" ixy="0" ixz="0" iyy="1.417e-05" iyz="0" izz="1.208e-05"/>
    </inertial>
  </link>
  <joint name="charuco_dmy_joint" type="fixed">
    <parent link="map"/>
    <child link="charuco_dmy_link"/>
    <origin rpy="0 0 0" xyz="-0.40 0.31 -0.019"/>
  </joint>
  <link name="charuco_link"/>
  <joint name="charuco_joint" type="fixed">
    <parent link="charuco_dmy_link"/>
    <child link="charuco_link"/>
    <origin rpy="0 0 -1.5714" xyz="0 0 0"/>
  </joint>
</robot>

